{"uuid": "42415877-cf72-4be3-a1a1-9c430348cff4", "children": ["e1933410-3899-4e6a-b255-1fa654a6f897"], "befores": [{"name": "_xunit_setup_method_fixture_TestIntroPage", "status": "broken", "statusDetails": {"message": "selenium.common.exceptions.WebDriverException: Message: unknown error: net::ERR_CONNECTION_RESET\n  (Session info: chrome=114.0.5735.199)\nStacktrace:\nBacktrace:\n\tGetHandleVerifier [0x0082A813+48355]\n\t(No symbol) [0x007BC4B1]\n\t(No symbol) [0x006C5358]\n\t(No symbol) [0x006C1B33]\n\t(No symbol) [0x006B8CA5]\n\t(No symbol) [0x006B9D0A]\n\t(No symbol) [0x006B9003]\n\t(No symbol) [0x006B8355]\n\t(No symbol) [0x006B82EC]\n\t(No symbol) [0x006B6F26]\n\t(No symbol) [0x006B7688]\n\t(No symbol) [0x006C6B52]\n\t(No symbol) [0x0071CF01]\n\t(No symbol) [0x0070A73C]\n\t(No symbol) [0x0071C922]\n\t(No symbol) [0x0070A536]\n\t(No symbol) [0x006E82DC]\n\t(No symbol) [0x006E93DD]\n\tGetHandleVerifier [0x00A8AABD+2539405]\n\tGetHandleVerifier [0x00ACA78F+2800735]\n\tGetHandleVerifier [0x00AC456C+2775612]\n\tGetHandleVerifier [0x008B51E0+616112]\n\t(No symbol) [0x007C5F8C]\n\t(No symbol) [0x007C2328]\n\t(No symbol) [0x007C240B]\n\t(No symbol) [0x007B4FF7]\n\tBaseThreadInitThunk [0x76C60099+25]\n\tRtlGetAppContainerNamedObjectPath [0x77C17B6E+286]\n\tRtlGetAppContainerNamedObjectPath [0x77C17B3E+238]\n\n", "trace": "  File \"C:\\Users\\evgenyp\\Cellenium\\venv\\lib\\site-packages\\pluggy\\_callers.py\", line 39, in _multicall\n    res = hook_impl.function(*args)\n  File \"C:\\Users\\evgenyp\\Cellenium\\venv\\lib\\site-packages\\_pytest\\fixtures.py\", line 1130, in pytest_fixture_setup\n    result = call_fixture_func(fixturefunc, request, kwargs)\n  File \"C:\\Users\\evgenyp\\Cellenium\\venv\\lib\\site-packages\\_pytest\\fixtures.py\", line 902, in call_fixture_func\n    fixture_result = next(generator)\n  File \"C:\\Users\\evgenyp\\Cellenium\\venv\\lib\\site-packages\\_pytest\\python.py\", line 907, in xunit_setup_method_fixture\n    _call_with_optional_argument(func, method)\n  File \"C:\\Users\\evgenyp\\Cellenium\\venv\\lib\\site-packages\\_pytest\\python.py\", line 787, in _call_with_optional_argument\n    func()\n  File \"C:\\Users\\evgenyp\\Cellenium\\tests\\google\\test_navigation.py\", line 10, in setup\n    self.driver.get_web(web_link='https://nextgenkube.ai-logix.net/interactions', maximize_window=False)\n  File \"C:\\Users\\evgenyp\\Cellenium\\core\\infrastructure\\driver\\engine.py\", line 37, in get_web\n    self.driver.get(web_link)\n  File \"C:\\Users\\evgenyp\\Cellenium\\venv\\lib\\site-packages\\selenium\\webdriver\\remote\\webdriver.py\", line 355, in get\n    self.execute(Command.GET, {\"url\": url})\n  File \"C:\\Users\\evgenyp\\Cellenium\\venv\\lib\\site-packages\\selenium\\webdriver\\remote\\webdriver.py\", line 346, in execute\n    self.error_handler.check_response(response)\n  File \"C:\\Users\\evgenyp\\Cellenium\\venv\\lib\\site-packages\\selenium\\webdriver\\remote\\errorhandler.py\", line 245, in check_response\n    raise exception_class(message, screen, stacktrace)\n"}, "start": 1688910338058, "stop": 1688910425049}], "start": 1688910338058, "stop": 1688910425469}